<?xml version="1.0" ?>


<robot name="myfirst" xmlns:xacro="http://www.ros.org/wiki/xacro">
 
    <xacro:property name="lower" value="-1.5708" />
    <xacro:property name="upper" value="1.5708" />

    <link name="base_link">
        <visual>
            <origin rpy="0 0 0" xyz="0 0 0"/>
            <geometry>
                <box size="1 1 1"/>
            </geometry>
        </visual>
        <collision>
            <origin rpy="0 0 0" xyz="0 0 0"/>
            <geometry>
                <box size="1 1 1"/>
            </geometry>
        </collision>
    </link>
    
    <joint name="base_link__link_01" type="revolute">
        <axis xyz="0 0 0.5" />
        <limit effort="1000.0" lower="${lower}" upper="${upper}" velocity="0.5" />
        <origin rpy="0 0 0" xyz="0 0 0.5"/>
        <parent link="base_link"/>
        <child link="link1"/>
    </joint>
    
    <link name="link1">
        <visual>
            <origin rpy="0 0 0" xyz="0 0 0.2"/>
            <geometry>
                <cylinder radius="0.35" length="0.4"/>
            </geometry>
        </visual>
        <collision>
            <origin rpy="0 0 0" xyz="0 0 0.2"/>
            <geometry>
                <cylinder radius="0.35" length="0.4"/>
            </geometry>
        </collision>
    </link>


    <joint name="link_01__link_02" type="revolute">
        <axis xyz="0 0.4 0" />
        <limit effort="1000.0" lower="${lower}" upper="${upper}" velocity="0.5" />
        <origin rpy="0 0 0" xyz="0 0 0.4"/>
        <parent link="link1"/>
        <child link="link2"/>
    </joint>

    <link name="link2">
        <visual>
            <origin rpy="0 0 0" xyz="0 0 0.4"/>
            <geometry>
                <cylinder radius="0.15" length="0.8"/>
            </geometry>
        </visual>
        <collision>
            <origin rpy="0 0 0" xyz="0 0 0.4"/>
            <geometry>
                <cylinder radius="0.15" length="0.8"/>
            </geometry>
        </collision>
    </link>

    <joint name="link_02__link_03" type="revolute">
        <axis xyz="0 0.8 0" />
        <limit effort="1000.0" lower="${lower}" upper="${upper}" velocity="0.5" />
        <origin rpy="0 0 0" xyz="0 0 0.8"/>
        <parent link="link2"/>
        <child link="link3"/>
    </joint>

    <link name="link3">
        <visual>
            <origin rpy="0 0 0" xyz="0 0 0.4"/>
            <geometry>
                <cylinder radius="0.15" length="0.8"/>
            </geometry>
        </visual>
        <collision>
            <origin rpy="0 0 0" xyz="0 0 0.4"/>
            <geometry>
                <cylinder radius="0.15" length="0.8"/>
            </geometry>
        </collision>
    </link>

    <joint name="link_03__link_04" type="revolute">
        <axis xyz="0 0.8 0" />
        <limit effort="1000.0" lower="${lower}" upper="${upper}" velocity="0.5" />
        <origin rpy="0 0 0" xyz="0 0 0.8"/>
        <parent link="link3"/>
        <child link="link4"/>
    </joint>

    <link name="link4">
        <visual>
            <origin rpy="0 0 0" xyz="0 0 0.4"/>
            <geometry>
                <cylinder radius="0.15" length="0.8"/>
            </geometry>
        </visual>
        <collision>
            <origin rpy="0 0 0" xyz="0 0 0.4"/>
            <geometry>
                <cylinder radius="0.15" length="0.8"/>
            </geometry>
        </collision>
    </link>
     <joint name="link_04__link_05" type="revolute">
        <axis xyz="0 0.8 0" />
        <limit effort="1000.0" lower="${lower}" upper="${upper}" velocity="0.5" />
        <origin rpy="0 0 0" xyz="0 0 0.8"/>
        <parent link="link4"/>
        <child link="link5"/>
    </joint>

    <link name="link5">
        <visual>
            <origin rpy="0 0 0" xyz="0 0 0.4"/>
            <geometry>
                <cylinder radius="0.15" length="0.8"/>
            </geometry>
        </visual>
        <collision>
            <origin rpy="0 0 0" xyz="0 0 0.4"/>
            <geometry>
                <cylinder radius="0.15" length="0.8"/>
            </geometry>
        </collision>
    </link>

    <gazebo>
      <plugin name="gazebo_ros_control" filename="libgazebo_ros_control.so">
      </plugin>
    </gazebo>

</robot>